{"name": "Неуспешный логин с неверными учетными данными - возвращается ожидаемое сообщение", "status": "passed", "parameters": [{"name": "wrong_field", "value": "'password'"}], "start": 1748983340673, "stop": 1748983340969, "uuid": "c53322b7-c9c8-4f46-bf2f-211c7ad908c3", "historyId": "b59e6181d359a15d9673457b970f8699", "testCaseId": "edf1aad5cbc6f9cc3395edceaae049f1", "fullName": "tests.test_user_login.TestUserLogin#test_login_invalid_credentials_message", "labels": [{"name": "feature", "value": "Логин пользователя"}, {"name": "parentSuite", "value": "tests"}, {"name": "suite", "value": "test_user_login"}, {"name": "subSuite", "value": "TestUserLogin"}, {"name": "host", "value": "MaxPro"}, {"name": "thread", "value": "2704-MainThread"}, {"name": "framework", "value": "pytest"}, {"name": "language", "value": "cpython3"}, {"name": "package", "value": "tests.test_user_login"}]}